Workbook

Sheet Slides+PNGs
A1: Slide # (unreliable) | B1: Slide Code (new) | C1: 2025-10 Status | D1: 2025-10 Comments | E1: Slide section | F1: Slide title text | G1: Slide description | H1: IGME data Issue? | I1: GHE data issue? | J1: WHO Map issue? | K1: New Data? | L1: Other data issue? | M1: PNG input | N1: PNG data source 1 | O1: Slide Citation | P1: Date Created | Q1: Created / Provided by | R1: Updated data expected | S1: Comment
A2: 1 | B2: TITLE | C2: DONE | E2: Master title | F2: Master title | G2: Title slide | H2: N/A | I2: N/A | J2: N/A | L2: N/A | M2: N/A | N2: =INDEX(PNGs!$J:J,MATCH($M2,PNGs!B:B,0)) -> #N/A | O2: N/A | P2: N/A | Q2: N/A | R2: N/A
A3: 2 | B3: MAT-MORTALITY-NA-TITLE-TEXT | C3: DONE | E3: Maternal mortality | F3: Maternal mortality | G3: Title slide | H3: N/A | I3: N/A | J3: N/A | K3: N/A | L3: N/A | M3: N/A | N3: =INDEX(PNGs!$J:J,MATCH($M3,PNGs!B:B,0)) -> #N/A | O3: N/A | P3: N/A | Q3: N/A | R3: N/A
A4: 3 | B4: MAT-MORTALITY-GLOBAL-MMR-MAP | C4: DONE | E4: Maternal mortality | F4: Maternal deaths per 100 000 live births (MMR), 2023 | G4: Map | H4: N/A | I4: N/A | J4: FALSE | K4: FALSE | L4: FALSE | M4: Other | N4: Report | O4: United Nations Maternal Mortality Estimation Inter-Agency Group (MMEIG) | P4: 45727 | Q4: STRONG, Kathleen Louise strongk@who.int
A5: 4 | B5: MAT-MORTALITY-GLOBAL-MMR&DEATHS-TREND | C5: Issue | D5: SRH: equivalent to estimates_World.csv and estimates_WHO_region.csv and estimates_World_Bank_Income.csvavailable? Or should we use GHO data? | E5: Maternal mortality | F5: Maternal mortality: 287,000 maternal deaths in 2020 | G5: Maternal mortality ratio + Number of maternal deaths | H5: N/A | I5: N/A | J5: N/A | M5: Maternal_MMR_trends2000-2020_dim2.png | N5: =INDEX(PNGs!$J:J,MATCH($M5,PNGs!B:B,0)) -> estimates_World.csv | O5: Trends in maternal mortality 2000 to 2020: estimates by WHO, UNICEF, UNFPA, World Bank Group and UNDESA/Population Division. Geneva: World Health Organization; 2023 | P5: 2023-05 | Q5: PEVEN, Kimberly pevenk@who.int / kpeven@gmail.com | S5: The png is used twice, but this one feels like it is the correct one.
A6: 4 | B6: MAT-MORTALITY-GLOBAL-MMR&DEATHS-TREND | C6: Issue | D6: SRH: equivalent to estimates_World.csv and estimates_WHO_region.csv and estimates_World_Bank_Income.csvavailable? Or should we use GHO data? | E6: Maternal mortality | F6: Maternal mortality: 287,000 maternal deaths in 2020 | G6: Maternal mortality ratio + Number of maternal deaths | H6: N/A | I6: N/A | J6: N/A | M6: Maternal_numDeaths_trends2000-2020_dim2.png | N6: =INDEX(PNGs!$J:J,MATCH($M6,PNGs!B:B,0)) -> estimates_World.csv | O6: Trends in maternal mortality 2000 to 2020: estimates by WHO, UNICEF, UNFPA, World Bank Group and UNDESA/Population Division. Geneva: World Health Organization; 2023 | P6: 2023-05 | Q6: PEVEN, Kimberly pevenk@who.int / kpeven@gmail.com
A7: 5 | B7: MAT-MORTALITY-GLOBAL-MMR-TREND | C7: Issue | D7: SRH: equivalent to estimates_World.csv and estimates_WHO_region.csv and estimates_World_Bank_Income.csvavailable? Or should we use GHO data? | E7: Maternal mortality | F7: Maternal mortality: 287,000 maternal deaths in 2020 | G7: Maternal mortality ratio | H7: N/A | I7: N/A | J7: N/A | M7: Maternal_MMR_trends2000-2020_dim1.png | N7: =INDEX(PNGs!$J:J,MATCH($M7,PNGs!B:B,0)) -> estimates_World.csv | O7: Trends in maternal mortality 2000 to 2020: estimates by WHO, UNICEF, UNFPA, World Bank Group and UNDESA/Population Division. Geneva: World Health Organization; 2023 | P7: 2023-05 | Q7: PEVEN, Kimberly pevenk@who.int / kpeven@gmail.com
A8: 6 | B8: MAT-MORTALITY-GLOBAL-DEATHS-TREND | C8: Issue | D8: SRH: equivalent to estimates_World.csv and estimates_WHO_region.csv and estimates_World_Bank_Income.csvavailable? Or should we use GHO data? | E8: Maternal mortality | F8: Maternal mortality: 287,000 maternal deaths in 2020 | G8: Number of maternal deaths | H8: N/A | I8: N/A | J8: N/A | M8: Maternal_numDeaths_trends2000-2020_dim1.png | N8: =INDEX(PNGs!$J:J,MATCH($M8,PNGs!B:B,0)) -> estimates_World.csv | O8: Trends in maternal mortality 2000 to 2020: estimates by WHO, UNICEF, UNFPA, World Bank Group and UNDESA/Population Division. Geneva: World Health Organization; 2023 | P8: 2023-05 | Q8: PEVEN, Kimberly pevenk@who.int / kpeven@gmail.com
A9: 7 | B9: MAT-MORTALITY-WHOREGION-MMR-TREND | C9: Issue | D9: SRH: equivalent to estimates_World.csv and estimates_WHO_region.csv and estimates_World_Bank_Income.csvavailable? Or should we use GHO data? | E9: Maternal mortality | F9: Maternal mortality ratio | G9: Maternal mortality ratio by WHO region | H9: N/A | I9: N/A | J9: N/A | M9: Maternal_MMR_trends_WHOreg_2000-2020_dim1.png | N9: =INDEX(PNGs!$J:J,MATCH($M9,PNGs!B:B,0)) -> estimates_WHO_region.csv | O9: Trends in maternal mortality 2000 to 2020: estimates by WHO, UNICEF, UNFPA, World Bank Group and UNDESA/Population Division. Geneva: World Health Organization; 2023 | P9: 2023-05 | Q9: PEVEN, Kimberly pevenk@who.int / kpeven@gmail.com
A10: 8 | B10: MAT-MORTALITY-WBINCOME-MMR-TREND | C10: Issue | D10: SRH: equivalent to estimates_World_Bank_Income.csvavailable? | E10: Maternal mortality | F10: Maternal mortality ratio | G10: Maternal mortality ratio by Income | H10: N/A | I10: N/A | J10: N/A | M10: Maternal_MMR_trends_income_2000-2020_dim1.png | N10: =INDEX(PNGs!$J:J,MATCH($M10,PNGs!B:B,0)) -> estimates_World_Bank_Income.csv | O10: Trends in maternal mortality 2000 to 2020: estimates by WHO, UNICEF, UNFPA, World Bank Group and UNDESA/Population Division. Geneva: World Health Organization; 2023 | P10: 2023-05 | Q10: PEVEN, Kimberly pevenk@who.int / kpeven@gmail.com
A11: 9 | B11: MAT-MORTALITY-GLOBAL-COD-VERTSTACK | C11: Issue | D11: SRH: has Say2014_LGH_MatCauseDeath.xlsx been updated? | E11: Maternal mortality | F11: Maternal Causes of Death, 2014 | G11: Maternal Causes of Death, 2014 - stacked vertical bar graph | H11: N/A | I11: N/A | J11: N/A | M11: Maternal_CauseDeath_stackBar_Say_LGH_2014.png | N11: =INDEX(PNGs!$J:J,MATCH($M11,PNGs!B:B,0)) -> Say2014_LGH_MatCauseDeath.xlsx | O11: Say et al, Lancet Global Health, 2014 | P11: 2021-11 | Q11: PEVEN, Kimberly pevenk@who.int / kpeven@gmail.com
A12: 10 | B12: MAT-MORTALITY-GLOBAL-COD-PIE | C12: Issue | D12: SRH: has Say2014_LGH_MatCauseDeath.xlsx been updated? | E12: Maternal mortality | F12: Maternal Causes of Death, 2014 | G12: Maternal Causes of Death, 2014 - Pie chart | H12: N/A | I12: N/A | J12: N/A | M12: Maternal_CauseDeath_pie_Say_LGH_2014.png | N12: =INDEX(PNGs!$J:J,MATCH($M12,PNGs!B:B,0)) -> Say2014_LGH_MatCauseDeath.xlsx | O12: Say et al, Lancet Global Health, 2014 | P12: 2021-11 | Q12: PEVEN, Kimberly pevenk@who.int / kpeven@gmail.com
A13: 11 | B13: MAT-STILBIRTH-NA-TITLE-TEXT | C13: DONE | E13: Stillbirth | F13: Stillbirth | G13: Title slide | H13: N/A | I13: N/A | J13: N/A | L13: N/A | M13: N/A | N13: =INDEX(PNGs!$J:J,MATCH($M13,PNGs!B:B,0)) -> #N/A | O13: N/A | P13: N/A | Q13: N/A | R13: N/A
A14: 12 | B14: MAT-STILBIRTH-GLOBAL-NUMBER&RATE-TREND | E14: Stillbirth | F14: 1.9 babies were born stillbirth in 2021 | G14: Number of stillbirths + Stillbirth rate (Global) | H14: N/A | I14: N/A | J14: N/A | L14: FALSE | M14: Other | N14: =INDEX(PNGs!$J:J,MATCH($M14,PNGs!B:B,0)) -> 0 | O14: UN-IGME Never Forgotten: The situation of stillbirth around the globe, 2023 | P14: ? | R14: ?
A15: 13 | B15: MAT-STILBIRTH-GLOBAL-RATE_NEONATAL_STILLBIRTH-TREND | E15: Stillbirth | F15: 1.9 babies were born stillbirth in 2021 | G15: Neonatal mortality rate + Stillbirth rate | H15: Dodged | I15: N/A | J15: N/A | M15: nmr_stillbirth.png | N15: =INDEX(PNGs!$J:J,MATCH($M15,PNGs!B:B,0)) -> Stillbirth-rate-and-deaths_2023.xlsx | O15: UN-IGME Never Forgotten: The situation of stillbirth around the globe, 2023 | P15: 2024-04 | S15: Data came directly from IGME, so not impacted by MCA error
A16: 14 | B16: MAT-STILBIRTH-NA-DEFINITIONS-INFO | E16: Stillbirth | F16: Clear definitions are needed for international comparisons | G16: Timeline | H16: N/A | I16: N/A | J16: N/A | L16: FALSE | M16: Other | N16: =INDEX(PNGs!$J:J,MATCH($M16,PNGs!B:B,0)) -> 0 | O16: UN-IGME Never Forgotten: The situation of stillbirth around the globe, 2023 | P16: ? | R16: ?
A17: 15 | B17: MAT-STILBIRTH-GLOBAL-LOCATION-MAP | E17: Stillbirth | F17: Where do most stillbirths take place? | G17: Map | H17: N/A | I17: N/A | J17: FALSE | L17: FALSE | M17: Other | N17: =INDEX(PNGs!$J:J,MATCH($M17,PNGs!B:B,0)) -> 0 | O17: UN-IGME Never Forgotten: The situation of stillbirth around the globe, 2023 | P17: ? | R17: ?
A18: 16 | B18: MAT-STILBIRTH-GLOBAL-TIMING-MAP | E18: Stillbirth | F18: When do most stillbirths occur? | G18: Map | H18: N/A | I18: N/A | J18: FALSE | L18: FALSE | M18: Other | N18: =INDEX(PNGs!$J:J,MATCH($M18,PNGs!B:B,0)) -> 0 | O18: UN-IGME Never Forgotten: The situation of stillbirth around the globe, 2023 | P18: ? | R18: ?
A19: 17 | B19: MAT-STILBIRTH-GLOBAL-TRENDS-MAP | E19: Stillbirth | F19: If current trends continue | G19: Map | H19: N/A | I19: N/A | J19: FALSE | L19: FALSE | M19: Other | N19: =INDEX(PNGs!$J:J,MATCH($M19,PNGs!B:B,0)) -> 0 | O19: UN-IGME Never Forgotten: The situation of stillbirth around the globe, 2023 | P19: ? | R19: ?
A20: 18 | B20: MAT-STILBIRTH-NA-REQUIREMENTS_ENDING-INFO | E20: Stillbirth | F20: Requirements for ending preventable stillbirths | G20: bullet points | H20: N/A | I20: N/A | J20: N/A | L20: FALSE | M20: Other | N20: =INDEX(PNGs!$J:J,MATCH($M20,PNGs!B:B,0)) -> 0 | O20: UN-IGME Never Forgotten: The situation of stillbirth around the globe, 2023 | P20: ? | R20: ?
A21: 19 | B21: NEW-MORTALITY-NA-TITLE-TEXT | C21: DONE | E21: Neonatal mortality | F21: Neonatal mortality | G21: Title slide | H21: N/A | I21: N/A | J21: N/A | L21: N/A | M21: N/A | N21: =INDEX(PNGs!$J:J,MATCH($M21,PNGs!B:B,0)) -> #N/A | O21: N/A | P21: N/A | Q21: N/A | R21: N/A
A22: 20 | B22: NEW-MORTALITY-GLOBAL-NMR-MAP | E22: Neonatal mortality | F22: Neonatal mortality | G22: Neonatal mortality rate map | H22: N/A | I22: N/A | J22: FALSE | L22: FALSE | M22: Other | N22: https://childmortality.org/wp-content/uploads/2024/03/UNIGME-2023-Child-Mortality-Report.pdf | O22: United Nations Inter-agency Group for Child Mortality Estimation (UN IGME), Levels & Trends in Child Mortality: Report 2023, Estimates developed by the United Nations Inter-agency Group for Child Mortality Estimation, United Nations Children’s Fund, New York, 2024 | R22: 2025-04
A23: 21 | B23: NEW-MORTALITY-GLOBAL-NMR&DEATHS-TREND | E23: Neonatal mortality | F23: 2.3 million deaths in 2022 | G23: Neonatal Mortality rates + neonatal number of deaths (global) | H23: Dodged | I23: N/A | J23: N/A | M23: 2023unigme_deaths_nmr_dim2.png | N23: =INDEX(PNGs!$J:J,MATCH($M23,PNGs!B:B,0)) -> UNIGME-2023-SDGRegion-Rates-Deaths-Under-five.xlsx | O23: United Nations Inter-agency Group for Child Mortality Estimation (UN IGME), Levels & Trends in Child Mortality: Report 2023, Estimates developed by the United Nations Inter-agency Group for Child Mortality Estimation, United Nations Children’s Fund, New York, 2024 | P23: 2024-04 | R23: 2025-04 | S23: Data came directly from IGME, so not impacted by MCA error
A24: 21 | B24: NEW-MORTALITY-GLOBAL-NMR&DEATHS-TREND | E24: Neonatal mortality | F24: 2.3 million deaths in 2022 | G24: Neonatal Mortality rates + neonatal number of deaths (global) | H24: Dodged | I24: N/A | J24: N/A | M24: 2023unigme_rates_nmr_dim2.png | N24: =INDEX(PNGs!$J:J,MATCH($M24,PNGs!B:B,0)) -> UNIGME-2023-SDGRegion-Rates-Deaths-Under-five.xlsx | O24: United Nations Inter-agency Group for Child Mortality Estimation (UN IGME), Levels & Trends in Child Mortality: Report 2023, Estimates developed by the United Nations Inter-agency Group for Child Mortality Estimation, United Nations Children’s Fund, New York, 2024 | P24: 2024-04 | R24: 2025-04 | S24: Data came directly from IGME, so not impacted by MCA error
A25: 22 | B25: NEW-MORTALITY-GLOBAL-RATE&DEATHS_NMR&IMR-TREND | E25: Neonatal mortality | F25: 2.3 million deaths in 2022 | G25: Neonatal Mortality rates + neonatal number of deaths (global) Infant Mortality rates + Infant number of deaths (global) | H25: Dodged | I25: N/A | J25: N/A | M25: 2023unigme_deaths_nmr_imr_dim2.png | N25: =INDEX(PNGs!$J:J,MATCH($M25,PNGs!B:B,0)) -> UNIGME-2023-SDGRegion-Rates-Deaths-Under-five.xlsx | O25: United Nations Inter-agency Group for Child Mortality Estimation (UN IGME), Levels & Trends in Child Mortality: Report 2023, Estimates developed by the United Nations Inter-agency Group for Child Mortality Estimation, United Nations Children’s Fund, New York, 2024 | P25: 2024-04 | R25: 2025-04 | S25: Data came directly from IGME, so not impacted by MCA error
A26: 22 | B26: NEW-MORTALITY-GLOBAL-RATE&DEATHS_NMR&IMR-TREND | E26: Neonatal mortality | F26: 2.3 million deaths in 2022 | G26: Neonatal Mortality rates + neonatal number of deaths (global) Infant Mortality rates + Infant number of deaths (global) | H26: Dodged | I26: N/A | J26: N/A | M26: 2023unigme_rates_nmr_imr_dim2.png | N26: =INDEX(PNGs!$J:J,MATCH($M26,PNGs!B:B,0)) -> UNIGME-2023-SDGRegion-Rates-Deaths-Under-five.xlsx | O26: United Nations Inter-agency Group for Child Mortality Estimation (UN IGME), Levels & Trends in Child Mortality: Report 2023, Estimates developed by the United Nations Inter-agency Group for Child Mortality Estimation, United Nations Children’s Fund, New York, 2024 | P26: 2024-04 | R26: 2025-04 | S26: Data came directly from IGME, so not impacted by MCA error
A27: 23 | B27: NEW-MORTALITY-GLOBAL-RATE&DEATHS_NMR&IMR&CMR-TREND | E27: Neonatal mortality | F27: 2.3 million deaths in 2022 | G27: Neonatal Mortality rates + neonatal number of deaths (global) Infant Mortality rates + Infant number of deaths (global) Child Mortality rates + Child number of deaths (global) | H27: Dodged | I27: N/A | J27: N/A | M27: 2023unigme_deaths_nmr_imr_cmr_dim2.png | N27: =INDEX(PNGs!$J:J,MATCH($M27,PNGs!B:B,0)) -> UNIGME-2023-SDGRegion-Rates-Deaths-Under-five.xlsx | O27: United Nations Inter-agency Group for Child Mortality Estimation (UN IGME), Levels & Trends in Child Mortality: Report 2023, Estimates developed by the United Nations Inter-agency Group for Child Mortality Estimation, United Nations Children’s Fund, New York, 2024 | P27: 2024-04 | R27: 2025-04 | S27: Data came directly from IGME, so not impacted by MCA error
A28: 23 | B28: NEW-MORTALITY-GLOBAL-RATE&DEATHS_NMR&IMR&CMR-TREND | E28: Neonatal mortality | F28: 2.3 million deaths in 2022 | G28: Neonatal Mortality rates + neonatal number of deaths (global) Infant Mortality rates + Infant number of deaths (global) Child Mortality rates + Child number of deaths (global) | H28: Dodged | I28: N/A | J28: N/A | M28: 2023unigme_rates_nmr_imr_cmr_dim2.png | N28: =INDEX(PNGs!$J:J,MATCH($M28,PNGs!B:B,0)) -> UNIGME-2023-SDGRegion-Rates-Deaths-Under-five.xlsx | O28: United Nations Inter-agency Group for Child Mortality Estimation (UN IGME), Levels & Trends in Child Mortality: Report 2023, Estimates developed by the United Nations Inter-agency Group for Child Mortality Estimation, United Nations Children’s Fund, New York, 2024 | P28: 2024-04 | R28: 2025-04 | S28: Data came directly from IGME, so not impacted by MCA error
A29: 24 | B29: NEW-MORTALITY-GLOBAL-RATE&DEATHS_NMR&IMR&CMR&U5MR-TREND | E29: Neonatal mortality | F29: 2.3 million deaths in 2022 | G29: Neonatal Mortality rates + neonatal number of deaths (global) Infant Mortality rates + Infant number of deaths (global) Child Mortality rates + Child number of deaths (global) Under 5 Mortality rates + Under 5 number of deaths (global) | H29: Dodged | I29: N/A | J29: N/A | M29: 2023unigme_deaths_nmr_imr_cmr_u5mr_dim2.png | N29: =INDEX(PNGs!$J:J,MATCH($M29,PNGs!B:B,0)) -> UNIGME-2023-SDGRegion-Rates-Deaths-Under-five.xlsx | O29: United Nations Inter-agency Group for Child Mortality Estimation (UN IGME), Levels & Trends in Child Mortality: Report 2023, Estimates developed by the United Nations Inter-agency Group for Child Mortality Estimation, United Nations Children’s Fund, New York, 2024 | P29: 2024-04 | R29: 2025-04 | S29: Data came directly from IGME, so not impacted by MCA error
A30: 24 | B30: NEW-MORTALITY-GLOBAL-RATE&DEATHS_NMR&IMR&CMR&U5MR-TREND | E30: Neonatal mortality | F30: 2.3 million deaths in 2022 | G30: Neonatal Mortality rates + neonatal number of deaths (global) Infant Mortality rates + Infant number of deaths (global) Child Mortality rates + Child number of deaths (global) Under 5 Mortality rates + Under 5 number of deaths (global) | H30: Dodged | I30: N/A | J30: N/A | M30: 2023unigme_rates_nmr_imr_cmr_u5mr_dim2.png | N30: =INDEX(PNGs!$J:J,MATCH($M30,PNGs!B:B,0)) -> UNIGME-2023-SDGRegion-Rates-Deaths-Under-five.xlsx | O30: United Nations Inter-agency Group for Child Mortality Estimation (UN IGME), Levels & Trends in Child Mortality: Report 2023, Estimates developed by the United Nations Inter-agency Group for Child Mortality Estimation, United Nations Children’s Fund, New York, 2024 | P30: 2024-04 | R30: 2025-04 | S30: Data came directly from IGME, so not impacted by MCA error
A31: 25 | B31: NEW-MORTALITY-GLOBAL-RATE_NMR-TREND | E31: Neonatal mortality | F31: 2.3 million deaths in 2022 | G31: Neonatal Mortality rates (global) | H31: Dodged | I31: N/A | J31: N/A | M31: 2023unigme_rates_nmr_dim1.png | N31: =INDEX(PNGs!$J:J,MATCH($M31,PNGs!B:B,0)) -> UNIGME-2023-SDGRegion-Rates-Deaths-Under-five.xlsx | O31: United Nations Inter-agency Group for Child Mortality Estimation (UN IGME), Levels & Trends in Child Mortality: Report 2023, Estimates developed by the United Nations Inter-agency Group for Child Mortality Estimation, United Nations Children’s Fund, New York, 2024 | P31: 2024-04 | R31: 2025-04 | S31: Data came directly from IGME, so not impacted by MCA error
A32: 26 | B32: NEW-MORTALITY-GLOBAL-RATE_NMR&IMR-TREND | E32: Neonatal mortality | F32: 2.3 million deaths in 2022 | G32: Neonatal Mortality rates Infant Mortality rates (global) | H32: Dodged | I32: N/A | J32: N/A | M32: 2023unigme_rates_nmr_imr_dim1.png | N32: =INDEX(PNGs!$J:J,MATCH($M32,PNGs!B:B,0)) -> UNIGME-2023-SDGRegion-Rates-Deaths-Under-five.xlsx | O32: United Nations Inter-agency Group for Child Mortality Estimation (UN IGME), Levels & Trends in Child Mortality: Report 2023, Estimates developed by the United Nations Inter-agency Group for Child Mortality Estimation, United Nations Children’s Fund, New York, 2024 | P32: 2024-04 | R32: 2025-04 | S32: Data came directly from IGME, so not impacted by MCA error
A33: 27 | B33: NEW-MORTALITY-GLOBAL-RATE_NMR&IMR&CMR-TREND | E33: Neonatal mortality | F33: 2.3 million deaths in 2022 | G33: Neonatal Mortality rates Infant Mortality rates Child Mortality rates (global) | H33: Dodged | I33: N/A | J33: N/A | M33: 2023unigme_rates_nmr_imr_cmr_dim1.png | N33: =INDEX(PNGs!$J:J,MATCH($M33,PNGs!B:B,0)) -> UNIGME-2023-SDGRegion-Rates-Deaths-Under-five.xlsx | O33: United Nations Inter-agency Group for Child Mortality Estimation (UN IGME), Levels & Trends in Child Mortality: Report 2023, Estimates developed by the United Nations Inter-agency Group for Child Mortality Estimation, United Nations Children’s Fund, New York, 2024 | P33: 2024-04 | R33: 2025-04 | S33: Data came directly from IGME, so not impacted by MCA error. The png is used twice, but this one feels like it is the correct one.
A34: 28 | B34: NEW-MORTALITY-GLOBAL-RATE_NMR&IMR&CMR&U5MR-TREND | E34: Neonatal mortality | F34: 2.3 million deaths in 2022 | G34: Neonatal Mortality rates Infant Mortality rates Child Mortality rates Under 5 Mortality rates (global) | H34: Dodged | I34: N/A | J34: N/A | M34: 2023unigme_rates_nmr_imr_cmr_u5mr_dim1.png | N34: =INDEX(PNGs!$J:J,MATCH($M34,PNGs!B:B,0)) -> UNIGME-2023-SDGRegion-Rates-Deaths-Under-five.xlsx | O34: United Nations Inter-agency Group for Child Mortality Estimation (UN IGME), Levels & Trends in Child Mortality: Report 2023, Estimates developed by the United Nations Inter-agency Group for Child Mortality Estimation, United Nations Children’s Fund, New York, 2024 | P34: 2024-04 | R34: 2025-04
A35: 29 | B35: NEW-MORTALITY-GLOBAL-DEATHS_NEO-TREND | E35: Neonatal mortality | F35: 2.3 million deaths in 2022 | G35: Neonatal number of deaths (global) | H35: Dodged | I35: N/A | J35: N/A | M35: 2023unigme_deaths_nmr_dim1.png | N35: =INDEX(PNGs!$J:J,MATCH($M35,PNGs!B:B,0)) -> UNIGME-2023-SDGRegion-Rates-Deaths-Under-five.xlsx | O35: United Nations Inter-agency Group for Child Mortality Estimation (UN IGME), Levels & Trends in Child Mortality: Report 2023, Estimates developed by the United Nations Inter-agency Group for Child Mortality Estimation, United Nations Children’s Fund, New York, 2024 | P35: 2024-04 | R35: 2025-04 | S35: Data came directly from IGME, so not impacted by MCA error
A36: 30 | B36: NEW-MORTALITY-GLOBAL-DEATHS_NEO&INF-TREND | E36: Neonatal mortality | F36: 2.3 million deaths in 2022 | G36: Neonatal number of deaths (global) Infant number of deaths (global) | H36: Dodged | I36: N/A | J36: N/A | M36: 2023unigme_deaths_nmr_imr_dim1.png | N36: =INDEX(PNGs!$J:J,MATCH($M36,PNGs!B:B,0)) -> UNIGME-2023-SDGRegion-Rates-Deaths-Under-five.xlsx | O36: United Nations Inter-agency Group for Child Mortality Estimation (UN IGME), Levels & Trends in Child Mortality: Report 2023, Estimates developed by the United Nations Inter-agency Group for Child Mortality Estimation, United Nations Children’s Fund, New York, 2024 | P36: 2024-04 | R36: 2025-04 | S36: Data came directly from IGME, so not impacted by MCA error
A37: 31 | B37: NEW-MORTALITY-GLOBAL-DEATHS_NEO&INF&CHILD-TREND | E37: Neonatal mortality | F37: 2.3 million deaths in 2022 | G37: Neonatal number of deaths (global) Infant number of deaths (global) Child number of deaths | H37: Dodged | I37: N/A | J37: N/A | M37: 2023unigme_deaths_nmr_imr_cmr_dim1.png | N37: =INDEX(PNGs!$J:J,MATCH($M37,PNGs!B:B,0)) -> UNIGME-2023-SDGRegion-Rates-Deaths-Under-five.xlsx | O37: United Nations Inter-agency Group for Child Mortality Estimation (UN IGME), Levels & Trends in Child Mortality: Report 2023, Estimates developed by the United Nations Inter-agency Group for Child Mortality Estimation, United Nations Children’s Fund, New York, 2024 | P37: 2024-04 | R37: 2025-04 | S37: Data came directly from IGME, so not impacted by MCA error. The png is used twice, but this one feels like it is the correct one.
A38: 32 | B38: NEW-MORTALITY-GLOBAL-DEATHS_NEO&INF&CHILD&U5-TREND | E38: Neonatal mortality | F38: 2.3 million deaths in 2022 | G38: Neonatal number of deaths (global) Infant number of deaths (global) Child number of deaths Under 5 number of deaths (global) | H38: Dodged | I38: N/A | J38: N/A | M38: 2023unigme_deaths_nmr_imr_cmr_u5mr_dim1.png | N38: =INDEX(PNGs!$J:J,MATCH($M38,PNGs!B:B,0)) -> UNIGME-2023-SDGRegion-Rates-Deaths-Under-five.xlsx | O38: United Nations Inter-agency Group for Child Mortality Estimation (UN IGME), Levels & Trends in Child Mortality: Report 2023, Estimates developed by the United Nations Inter-agency Group for Child Mortality Estimation, United Nations Children’s Fund, New York, 2024 | P38: 2024-04 | R38: 2025-04
A39: 33 | B39: NEW-MORTALITY-GLOBAL-RATES&DEATHS_NEO&INF&CHILD&U5-BAR | E39: Neonatal mortality | F39: Global mortality rates & number of deaths by age, 2022 | G39: Mortality rates + Number of deaths (global) vertical bar | H39: Dodged | I39: N/A | J39: N/A | M39: deathsper1000_igme2023est_0to5.png | N39: =INDEX(PNGs!$J:J,MATCH($M39,PNGs!B:B,0)) -> fig 1 from 2023 unigme report (pg 12) | O39: United Nations Inter-agency Group for Child Mortality Estimation (UN IGME), Levels & Trends in Child Mortality: Report 2023, Estimates developed by the United Nations Inter-agency Group for Child Mortality Estimation, United Nations Children’s Fund, New York, 2024 | P39: 2024-04 | R39: 2025-04 | S39: Manually taken from IGME figure, so not impacted by MCA error. deathsper1000_igme2023est_0to5.png is used in two slides, but it is ok.
A40: 33 | B40: NEW-MORTALITY-GLOBAL-RATES&DEATHS_NEO&INF&CHILD&U5-BAR | E40: Neonatal mortality | F40: Global mortality rates & number of deaths by age, 2022 | G40: Mortality rates + Number of deaths (global) vertical bar | H40: Dodged | I40: N/A | J40: N/A | M40: percentagedeaths_igme2023est_0to5.png | N40: =INDEX(PNGs!$J:J,MATCH($M40,PNGs!B:B,0)) -> fig 1 from 2023 unigme report (pg 12) | O40: United Nations Inter-agency Group for Child Mortality Estimation (UN IGME), Levels & Trends in Child Mortality: Report 2023, Estimates developed by the United Nations Inter-agency Group for Child Mortality Estimation, United Nations Children’s Fund, New York, 2024 | P40: 2024-04 | R40: 2025-04 | S40: Manually taken from IGME figure, so not impacted by MCA error. percentagedeaths_igme2023est_0to5.png is used in two slides but it is ok.
...

Sheet Data sources
A1: Status | B1: code "order" | C1: Data Source (file name, api call, citation, etc.) | D1: Data file location | E1: Present in location? | F1: Present in R code? | G1: R code file | H1: R code chunk(s) | I1: Used in slides? (manually entered) | J1: Used in PNGs? | K1: Source detail | L1: Source Source | M1: Source Citation | N1: Comment
A2: Good | B2: 29.1 | C2: adol-cod-income.xlsx | D2: data/ | E2: TRUE | F2: TRUE | G2: slideset.Rmd | H2: updated-adol-mort | J2: =IF(OR(IF(ISERROR(VLOOKUP($C2,PNGs!J:J,1,FALSE)),FALSE,TRUE),IF(ISERROR(VLOOKUP($C2,PNGs!K:K,1,FALSE)),FALSE,TRUE),IF(ISERROR(VLOOKUP($C2,PNGs!L:L,1,FALSE)),FALSE,TRUE)), TRUE,FALSE) -> TRUE | K2: AD_MORT_TOP20 | L2: MCA | N2: Don't appear in slides: causedeaths_males-10-19_income2021r.png causedeaths_females-10-19_income2021r.png Appear in slides: Cause_specific_2010.2021_10.14ym_top5_income.png Cause_specific_2010.2021_15.19ym_top5_income.png Cause_specific_2010.2021_10.14yf_top5_income.png Cause_specific_2010.2021_15.19yf_top5_income.png
A3: Good | B3: 29.2 | C3: adol-cod-region.xlsx | D3: data/ | E3: TRUE | F3: TRUE | G3: slideset.Rmd | H3: updated-adol-mort | I3: TRUE | J3: =IF(OR(IF(ISERROR(VLOOKUP($C3,PNGs!J:J,1,FALSE)),FALSE,TRUE),IF(ISERROR(VLOOKUP($C3,PNGs!K:K,1,FALSE)),FALSE,TRUE),IF(ISERROR(VLOOKUP($C3,PNGs!L:L,1,FALSE)),FALSE,TRUE)), TRUE,FALSE) -> TRUE | K3: AD_MORT_TOP20 | L3: MCA | N3: Don't appear in slides: Cause_specific_2010.2021_10.14yf_top5_regional.png Cause_specific_2010.2021_15.19yf_top5_regional.png Appear in slides: causedeaths_males-10-19_regional2021.png causedeaths_females-10-19_regional2021.png Cause_specific_2010.2021_10.14ym_top5_regional.png Cause_specific_2010.2021_15.19ym_top5_regional.png causeSpec-rates-10-19_global2021.png Cause_specific_2007.2021_10.14ym_top5.png Cause_specific_2007.2021_15.19ym_top5.png Cause_specific_2007.2021_10.14yf_top5.png Cause_specific_2007.2021_15.19yf_top5.png
A4: Good | B4: 29.5 | C4: adol-mort-income.xlsx | D4: data/ | E4: TRUE | F4: TRUE | G4: slideset.Rmd | H4: updated-adol-mort | I4: TRUE | J4: =IF(OR(IF(ISERROR(VLOOKUP($C4,PNGs!J:J,1,FALSE)),FALSE,TRUE),IF(ISERROR(VLOOKUP($C4,PNGs!K:K,1,FALSE)),FALSE,TRUE),IF(ISERROR(VLOOKUP($C4,PNGs!L:L,1,FALSE)),FALSE,TRUE)), TRUE,FALSE) -> TRUE | K4: AD_MORT_ALL | L4: MCA | N4: Appears in slides: mortrate_trends_income21.png
A5: Good | B5: 29.6 | C5: adol-mort-region.xlsx | D5: data/ | E5: TRUE | F5: TRUE | G5: slideset.Rmd | H5: updated-adol-mort | I5: TRUE | J5: =IF(OR(IF(ISERROR(VLOOKUP($C5,PNGs!J:J,1,FALSE)),FALSE,TRUE),IF(ISERROR(VLOOKUP($C5,PNGs!K:K,1,FALSE)),FALSE,TRUE),IF(ISERROR(VLOOKUP($C5,PNGs!L:L,1,FALSE)),FALSE,TRUE)), TRUE,FALSE) -> TRUE | K5: AD_MORT_ALL | L5: MCA | N5: Doesn't appear in slides: mortRates_10-19_2021_global.png Appears in slides: mortrate_trends_regional_2024.png
A6: Issue | B6: 0.99 | C6: unigme_2021_mortrates.csv | D6: ArcGIS/ | E6: TRUE | F6: TRUE | G6: slideset.Rmd | H6: newborn-mort-2021 | I6: TRUE? | J6: TRUE? | K6: UNIGME-2021-Country-Rates-Deaths-Under-five_reshape.csv | L6: UNIGME
A7: Good | B7: 28.99 | C7: fig 1 from 2023 unigme report (pg 12) | D7: data/ | E7: TRUE | F7: TRUE | G7: slideset.Rmd | H7: unigme_childmort21 | I7: TRUE | J7: =IF(OR(IF(ISERROR(VLOOKUP($C7,PNGs!J:J,1,FALSE)),FALSE,TRUE),IF(ISERROR(VLOOKUP($C7,PNGs!K:K,1,FALSE)),FALSE,TRUE),IF(ISERROR(VLOOKUP($C7,PNGs!L:L,1,FALSE)),FALSE,TRUE)), TRUE,FALSE) -> TRUE | K7: United Nations Inter-agency Group for Child Mortality Estimation (UN IGME), Levels & Trends in Child Mortality: Report 2023, Estimates developed by the United Nations Inter-agency Group for Child Mortality Estimation, United Nations Children’s Fund, New York, 2024 | L7: UNIGME | N7: Don't have the report file. But it is this: https://childmortality.org/wp-content/uploads/2024/03/UNIGME-2023-Child-Mortality-Report.pdf Added it to github Manually drawn from UNIGME report and generates PNGs: deathsper1000_igme2023est_0to5.png percentagedeaths_igme2023est_0to5.png
A8: Good | B8: 4 | C8: Stillbirth-rate-and-deaths_2023.xlsx | D8: data/external | E8: TRUE | F8: TRUE | G8: slideset.Rmd | H8: stillbirth_nmr | I8: TRUE | J8: =IF(OR(IF(ISERROR(VLOOKUP($C8,PNGs!J:J,1,FALSE)),FALSE,TRUE),IF(ISERROR(VLOOKUP($C8,PNGs!K:K,1,FALSE)),FALSE,TRUE),IF(ISERROR(VLOOKUP($C8,PNGs!L:L,1,FALSE)),FALSE,TRUE)), TRUE,FALSE) -> TRUE | K8: https://data.unicef.org/wp-content/uploads/2020/10/Stillbirth-rate-and-deaths_2023.xlsx | L8: UNICEF
A9: Issue | B9: 17.99 | C9: mpdsr_arcgis.csv | D9: ArcGIS/ | E9: TRUE | F9: TRUE | G9: slideset.Rmd | H9: mpdsr | I9: TRUE? | J9: TRUE? | K9: PolicySurvey_All.labels.xlsx | L9: SRMNCAH Policy Survey
A10: Good | B10: 1 | C10: https://xmart-api-public.who.int/REFMART/REF_COUNTRY | D10: NA | E10: NA | F10: TRUE | G10: slideset.Rmd | H10: setup | I10: NA | J10: TRUE | K10: https://xmart-api-public.who.int/REFMART/REF_COUNTRY | L10: https://xmart-api-public.who.int/REFMART/REF_COUNTRY
A11: Good | B11: 6 | C11: UNIGME2023.GHO.2024-04-29.KIM.csv | D11: data/ | E11: TRUE | F11: TRUE | G11: slideset.Rmd | H11: newborn-mort-igme21-regional | I11: TRUE | J11: =IF(OR(IF(ISERROR(VLOOKUP($C11,PNGs!J:J,1,FALSE)),FALSE,TRUE),IF(ISERROR(VLOOKUP($C11,PNGs!K:K,1,FALSE)),FALSE,TRUE),IF(ISERROR(VLOOKUP($C11,PNGs!L:L,1,FALSE)),FALSE,TRUE)), TRUE,FALSE) -> TRUE | K11: Gerard | L11: GHO/MCA | N11: Matches what is currently in MCA_FACT_DATA_AGGREGATED. (because taken from what I prepared for GHO and not from GHO originally so didn't get the errors that came when GHO went to MCA.)
A12: Issue | B12: 25.89 | C12: AGE_OVER60PCT.csv | D12: ArcGIS/ | E12: TRUE | F12: TRUE | G12: slideset.Rmd | H12: aging | I12: TRUE? | J12: TRUE? | K12: WPP2024_GEN_F01_DEMOGRAPHIC_INDICATORS_COMPACT.xlsx
A13: Issue | B13: 25.899 | C13: AGE_OVER60PCT20302050.csv | D13: ArcGIS/ | E13: TRUE | F13: TRUE | G13: slideset.Rmd | H13: aging | I13: TRUE? | J13: TRUE? | K13: WPP2024_GEN_F01_DEMOGRAPHIC_INDICATORS_COMPACT.xlsx
A14: Good | B14: 2 | C14: UNIGME-2023-SDGRegion-Rates-Deaths-Under-five.xlsx | D14: data/external | E14: TRUE | F14: TRUE | G14: slideset.Rmd | H14: newborn-mort-2021 | I14: TRUE | J14: =IF(OR(IF(ISERROR(VLOOKUP($C14,PNGs!J:J,1,FALSE)),FALSE,TRUE),IF(ISERROR(VLOOKUP($C14,PNGs!K:K,1,FALSE)),FALSE,TRUE),IF(ISERROR(VLOOKUP($C14,PNGs!L:L,1,FALSE)),FALSE,TRUE)), TRUE,FALSE) -> TRUE | K14: https://childmortality.org/#datasets | L14: UNIGME | N14: (need to concatenate the age group and estimate tame (lower,med,upper) in excel before importing e.g. U5MR_lower, =CONCAT(C15,"_lower"))
A15: Issue | B15: 25.8999 | C15: age_obesity_2016.csv | D15: ArcGIS/ | E15: TRUE | F15: TRUE | G15: slideset.Rmd | H15: aging | I15: TRUE? | J15: TRUE? | K15: https://xmart-api-public.who.int/MNCAH/MCA_FACT_DATA?$filter=INDICATOR_FK%20in%20(%22AC_ANEMIAPW%22,%22AC_ANEMIAWRA%22,%22BC_LBW%22)&$select=INDICATOR_FK,YEAR_FK,COUNTRY_FK,COUNTRY_FK__CODE,ValueNumeric,ValueLow,ValueHigh,ValueStdDev,ValueStdErr,Comments,AGEGROUP_FK,Answer_FK,CauseGHE_FK,CauseGHEChild_FK,CauseENVCAUSE_FK,DatasourceLong,DatasourceShort,ImpSan_FK,ImpWater_FK,LivingArrangements_FK,MEASDEF_FK,MOTHEREDUCATION_FK,ProficiencyLevel_FK,ResideLTA_FK,RESIDENCEAREA_FK,SABDefinition_FK,SEVERITY_FK,SEVERITYHEARING_FK,SEVERITYVISION_FK,SEX_FK,WEALTHQUINTILE_FK
A16: Issue | B16: 9 | C16: Copy of cause of death for under 5 age groups_2021_23052024.xlsx | D16: data/ | E16: TRUE | F16: TRUE | G16: slideset.Rmd | H16: neo-cod-cacode | I16: TRUE | J16: =IF(OR(IF(ISERROR(VLOOKUP($C16,PNGs!J:J,1,FALSE)),FALSE,TRUE),IF(ISERROR(VLOOKUP($C16,PNGs!K:K,1,FALSE)),FALSE,TRUE),IF(ISERROR(VLOOKUP($C16,PNGs!L:L,1,FALSE)),FALSE,TRUE)), TRUE,FALSE) -> TRUE | K16: email from kate strong may 23 2024 | L16: KATE | N16: Where does it originally come from CA-CODE? IGME?
A17: NA | B17: 0 | C17: NA | D17: NA | E17: NA | F17: NA | G17: NA | H17: NA | I17: NA | J17: =IF(OR(IF(ISERROR(VLOOKUP($C17,PNGs!J:J,1,FALSE)),FALSE,TRUE),IF(ISERROR(VLOOKUP($C17,PNGs!K:K,1,FALSE)),FALSE,TRUE),IF(ISERROR(VLOOKUP($C17,PNGs!L:L,1,FALSE)),FALSE,TRUE)), TRUE,FALSE) -> TRUE | K17: NA | N17: NA
A18: Issue | B18: 15 | C18: Cause-specific_ranking_All years.dta | D18: data/raw/ | E18: TRUE | F18: FALSE | G18: NA | H18: NA | I18: FALSE? | J18: TRUE | K18: cause specific data from regina. dta file was huge so converted to csv in stata and then to parquet in this script: cause_specific_convert.R | N18: See notes from Cause_specific_ranking_AllYears.parquet
A19: Issue | B19: 25.98 | C19: AGE_HALE60.csv | D19: ArcGIS/ | E19: TRUE | F19: TRUE | G19: slideset.Rmd | H19: aging | I19: TRUE? | J19: TRUE? | K19: https://xmart-api-public.who.int/MNCAH/MCA_FACT_DATA?$filter=INDICATOR_FK%20in%20(%22AC_ANEMIAPW%22,%22AC_ANEMIAWRA%22,%22BC_LBW%22)&$select=INDICATOR_FK,YEAR_FK,COUNTRY_FK,COUNTRY_FK__CODE,ValueNumeric,ValueLow,ValueHigh,ValueStdDev,ValueStdErr,Comments,AGEGROUP_FK,Answer_FK,CauseGHE_FK,CauseGHEChild_FK,CauseENVCAUSE_FK,DatasourceLong,DatasourceShort,ImpSan_FK,ImpWater_FK,LivingArrangements_FK,MEASDEF_FK,MOTHEREDUCATION_FK,ProficiencyLevel_FK,ResideLTA_FK,RESIDENCEAREA_FK,SABDefinition_FK,SEVERITY_FK,SEVERITYHEARING_FK,SEVERITYVISION_FK,SEX_FK,WEALTHQUINTILE_FK
A20: Issue | B20: 15.99 | C20: adol_cause_maps.csv | D20: ArcGIS/ | E20: TRUE | F20: TRUE | G20: slideset.Rmd | H20: adol-yll-yld-causeSpecific | I20: TRUE? | J20: TRUE? | K20: Cause_specific_ranking_AllYears.parquet
A21: Issue | B21: 3 | C21: UNIGME-2021-Country-Rates-Deaths-Under-five_reshape.csv | D21: data/external | E21: TRUE | F21: TRUE | G21: slideset.Rmd | H21: newborn-mort-2021 | I21: TRUE? | J21: =IF(OR(IF(ISERROR(VLOOKUP($C21,PNGs!J:J,1,FALSE)),FALSE,TRUE),IF(ISERROR(VLOOKUP($C21,PNGs!K:K,1,FALSE)),FALSE,TRUE),IF(ISERROR(VLOOKUP($C21,PNGs!L:L,1,FALSE)),FALSE,TRUE)), TRUE,FALSE) -> FALSE | K21: https://childmortality.org/#datasets | L21: https://childmortality.org/#datasets | N21: for arcgis. Not present. Creates ArcGIS/unigme_2021_mortrates.csv
A22: Good | B22: 21 | C22: https://xmart-api-public.who.int/MNCAH/MCA_FACT_DATA?$filter=INDICATOR_FK%20in%20(%22AC_A4V%22,%22MN_IRTSYR%22,%22WCAH_ANCSYP%22,%22BC_FPSMM%22,%22BC_BASHP%22,%22CANUT_EBF%22,%22CANUT_EIBF%22,%22MN_ARV_PMTCT%22,%22TECI_ORS%22,%22TECI_ORSZINC%22,%22TECI_PNEUHCP%22,%22PNC_MOM%22,%22PNC_NB%22,%22AC_PAB%22,%22WCAH_DTP3%22,%22WCAH_MCV2%22)&$select=INDICATOR_FK,YEAR_FK,COUNTRY_FK,COUNTRY_FK__CODE,ValueNumeric,ValueLow,ValueHigh,ValueStdDev,ValueStdErr,Comments,AGEGROUP_FK,Answer_FK,CauseGHE_FK,CauseGHEChild_FK,CauseENVCAUSE_FK,DatasourceLong,DatasourceShort,ImpSan_FK,ImpWater_FK,LivingArrangements_FK,MEASDEF_FK,MOTHEREDUCATION_FK,ProficiencyLevel_FK,ResideLTA_FK,RESIDENCEAREA_FK,SABDefinition_FK,SEVERITY_FK,SEVERITYHEARING_FK,SEVERITYVISION_FK,SEX_FK,WEALTHQUINTILE_F | D22: NA | E22: NA | F22: TRUE | G22: slideset.Rmd | H22: mat-newb-coverage-xmart | I22: TRUE | J22: TRUE | K22: https://xmart-api-public.who.int/MNCAH/MCA_FACT_DATA?$filter=INDICATOR_FK%20in%20(%22AC_A4V%22,%22MN_IRTSYR%22,%22WCAH_ANCSYP%22,%22BC_FPSMM%22,%22BC_BASHP%22,%22CANUT_EBF%22,%22CANUT_EIBF%22,%22MN_ARV_PMTCT%22,%22TECI_ORS%22,%22TECI_ORSZINC%22,%22TECI_PNEUHCP%22,%22PNC_MOM%22,%22PNC_NB%22,%22AC_PAB%22,%22WCAH_DTP3%22,%22WCAH_MCV2%22)&$select=INDICATOR_FK,YEAR_FK,COUNTRY_FK,COUNTRY_FK__CODE,ValueNumeric,ValueLow,ValueHigh,ValueStdDev,ValueStdErr,Comments,AGEGROUP_FK,Answer_FK,CauseGHE_FK,CauseGHEChild_FK,CauseENVCAUSE_FK,DatasourceLong,DatasourceShort,ImpSan_FK,ImpWater_FK,LivingArrangements_FK,MEASDEF_FK,MOTHEREDUCATION_FK,ProficiencyLevel_FK,ResideLTA_FK,RESIDENCEAREA_FK,SABDefinition_FK,SEVERITY_FK,SEVERITYHEARING_FK,SEVERITYVISION_FK,SEX_FK,WEALTHQUINTILE_F | L22: MCA | N22: Don't appear in slides: MNHcoverage_trend_median2015-2024.png MNHcoverage_Antenatal_trend_median2015-2024.png MNHcoverage_Antenatal_recent_median2020-2024.png MNHcoverage_wealth_pncNB_2016-2022.png MNHcoverage_wealth_pncMOM_2016-2022.png Appear in slides: MNHcoverage_recent_median2020-2024.png MNHcoverage_region_recent_medians2020-24.png Plus a bunch with inequalities_ as prefix and a variety of suffixes. Given the way the code is written it is hard to tell if all the pngs are used or not.
A23: Issue | B23: 5 | C23: arr_estimates.xlsx | D23: data/external/ | E23: TRUE | F23: TRUE | G23: slideset.Rmd | H23: stillbirth_nmr | I23: FALSE? | J23: =IF(OR(IF(ISERROR(VLOOKUP($C23,PNGs!J:J,1,FALSE)),FALSE,TRUE),IF(ISERROR(VLOOKUP($C23,PNGs!K:K,1,FALSE)),FALSE,TRUE),IF(ISERROR(VLOOKUP($C23,PNGs!L:L,1,FALSE)),FALSE,TRUE)), TRUE,FALSE) -> TRUE | K23: ? | L23: UNIGME? | N23: Not in github and no source listed
A24: Good | B24: 21.1 | C24: data_export_MNCAH_DM_Indicators_MNHcoveragekp.xlsx | D24: data/ | E24: TRUE | F24: TRUE | G24: slideset.Rmd | H24: mat-newb-coverage-xmart | I24: TRUE | J24: =IF(OR(IF(ISERROR(VLOOKUP($C24,PNGs!J:J,1,FALSE)),FALSE,TRUE),IF(ISERROR(VLOOKUP($C24,PNGs!K:K,1,FALSE)),FALSE,TRUE),IF(ISERROR(VLOOKUP($C24,PNGs!L:L,1,FALSE)),FALSE,TRUE)), TRUE,FALSE) -> TRUE | K24: https://extranet.who.int/xmart4/MNCAH/data/DM_Indicators | L24: MCA | N24: used with "#21" to get indicator titles.
A25: Issue | B25: 7 | C25: UNIGME_data_for_WHO_2021.xlsx | D25: data/external/ | E25: TRUE | F25: TRUE | G25: slideset.Rmd | H25: newborn-mort-igme21-regional | I25: FALSE? | J25: =IF(OR(IF(ISERROR(VLOOKUP($C25,PNGs!J:J,1,FALSE)),FALSE,TRUE),IF(ISERROR(VLOOKUP($C25,PNGs!K:K,1,FALSE)),FALSE,TRUE),IF(ISERROR(VLOOKUP($C25,PNGs!L:L,1,FALSE)),FALSE,TRUE)), TRUE,FALSE) -> TRUE | K25: unigme estimates from 2021 with WHO regions (from Gerard email 18 jan 2022) | L25: UNIGME | N25: Not in github, but I added it from my email. Is this not in use? Don't appear in slides: 2021unigme_rates_Regions_nmr_imr_cmr_u5mr.png 2021unigme_rates_Regions_nmr.png 2021unigme_rates_Regions_nmr_imr.png 2021unigme_rates_Regions_nmr_imr_cmr.png
A26: Question | B26: 10 | C26: estimates_World.csv | D26: data/external/ | E26: FALSE | F26: TRUE | G26: slideset.Rmd | H26: maternal-mort | I26: TRUE | J26: =IF(OR(IF(ISERROR(VLOOKUP($C26,PNGs!J:J,1,FALSE)),FALSE,TRUE),IF(ISERROR(VLOOKUP($C26,PNGs!K:K,1,FALSE)),FALSE,TRUE),IF(ISERROR(VLOOKUP($C26,PNGs!L:L,1,FALSE)),FALSE,TRUE)), TRUE,FALSE) -> TRUE | K26: https://mmr2020.srhr.org/data#download specifically: https://mmr2020.srhr.org/download_mmr_estimates.zip | L26: SRHR? GHO? | N26: Why this one? And not https://data.who.int/indicators/i/C071DCB/AC597B1 or https://platform.who.int/data/maternal-newborn-child-adolescent-ageing/indicator-explorer-new/MCA/maternal-mortality-ratio-(per-100-000-live-births) GERARD TODO: Compare
A27: Issue | B27: 18 | C27: GLOBAL_DATAFLOW_2009-2019_UNICEFdataWarehouseStillbirth210921.xlsx | D27: data/external/ | E27: TRUE | F27: TRUE | G27: slideset.Rmd | H27: stillbirths | I27: FALSE? | J27: =IF(OR(IF(ISERROR(VLOOKUP($C27,PNGs!J:J,1,FALSE)),FALSE,TRUE),IF(ISERROR(VLOOKUP($C27,PNGs!K:K,1,FALSE)),FALSE,TRUE),IF(ISERROR(VLOOKUP($C27,PNGs!L:L,1,FALSE)),FALSE,TRUE)), TRUE,FALSE) -> FALSE | K27: UNICEF…But from where exactly | N27: Chunk "stillbirths" creates "stillbirthsUNICEF" but then it doesn't seem to use them to generate pngs.
A28: Issue | B28: 20 | C28: https://ghoapi.azureedge.net/api/WHS_PBR | D28: NA | E28: NA | F28: TRUE | G28: slideset.Rmd | H28: mnh_riskfactors | I28: FALSE? | J28: =IF(OR(IF(ISERROR(VLOOKUP($C28,PNGs!J:J,1,FALSE)),FALSE,TRUE),IF(ISERROR(VLOOKUP($C28,PNGs!K:K,1,FALSE)),FALSE,TRUE),IF(ISERROR(VLOOKUP($C28,PNGs!L:L,1,FALSE)),FALSE,TRUE)), TRUE,FALSE) -> FALSE | K28: https://ghoapi.azureedge.net/api/WHS_PBR | N28: Chunk "mnh_riskfactors" creates "WHS_PBR" but then it doesn't seem to use them to generate pngs.
A29: Question | B29: 11 | C29: estimates_WHO_region.csv | D29: data/external/ | E29: FALSE | F29: TRUE | G29: slideset.Rmd | H29: maternal-mort | I29: TRUE | J29: =IF(OR(IF(ISERROR(VLOOKUP($C29,PNGs!J:J,1,FALSE)),FALSE,TRUE),IF(ISERROR(VLOOKUP($C29,PNGs!K:K,1,FALSE)),FALSE,TRUE),IF(ISERROR(VLOOKUP($C29,PNGs!L:L,1,FALSE)),FALSE,TRUE)), TRUE,FALSE) -> TRUE | K29: https://mmr2020.srhr.org/data#download specifically: https://mmr2020.srhr.org/download_mmr_estimates.zip | N29: Why this one? And not https://data.who.int/indicators/i/C071DCB/AC597B1 or https://platform.who.int/data/maternal-newborn-child-adolescent-ageing/indicator-explorer-new/MCA/maternal-mortality-ratio-(per-100-000-live-births) GERARD TODO: Compare
A30: Question | B30: 11.1 | C30: estimates_World_Bank_Income.csv | D30: data/external/ | E30: FALSE | F30: TRUE | G30: slideset.Rmd | H30: maternal-mort | I30: TRUE | J30: =IF(OR(IF(ISERROR(VLOOKUP($C30,PNGs!J:J,1,FALSE)),FALSE,TRUE),IF(ISERROR(VLOOKUP($C30,PNGs!K:K,1,FALSE)),FALSE,TRUE),IF(ISERROR(VLOOKUP($C30,PNGs!L:L,1,FALSE)),FALSE,TRUE)), TRUE,FALSE) -> TRUE | K30: https://mmr2020.srhr.org/data#download specifically: https://mmr2020.srhr.org/download_mmr_estimates.zip | N30: Why this one? And not https://data.who.int/indicators/i/C071DCB/AC597B1 or https://platform.who.int/data/maternal-newborn-child-adolescent-ageing/indicator-explorer-new/MCA/maternal-mortality-ratio-(per-100-000-live-births) GERARD TODO: Compare
A31: Issue | B31: 22 | C31: Maternal-and-Newborn-Health-Coverage-Database-August-2021.xlsx | D31: data/external/ | E31: TRUE | F31: TRUE | G31: slideset.Rmd | H31: mat-newb-coverage-old | I31: FALSE? | J31: =IF(OR(IF(ISERROR(VLOOKUP($C31,PNGs!J:J,1,FALSE)),FALSE,TRUE),IF(ISERROR(VLOOKUP($C31,PNGs!K:K,1,FALSE)),FALSE,TRUE),IF(ISERROR(VLOOKUP($C31,PNGs!L:L,1,FALSE)),FALSE,TRUE)), TRUE,FALSE) -> FALSE | K31: UNICEF | N31: Chunk "mat-newb-coverage-old" creates several datasets, but then doesn't seem to use them to generate pngs.
A32: Issue | B32: 22.1 | C32: WPP2019_POP_F01_1_TOTAL_POPULATION_BOTH_SEXES.xlsx | D32: data/external/ | E32: TRUE | F32: TRUE | G32: slideset.Rmd | H32: mnh_riskfactors ,mat-newb-coverage-old | I32: FALSE? | J32: FALSE | K32: UNPD WPP 2019 | N32: Chunk "mat-newb-coverage-old" creates several datasets, but then doesn't seem to use them to generate pngs.
A33: Question | B33: 12 | C33: Say2014_LGH_MatCauseDeath.xlsx | D33: data/external/ | E33: TRUE | F33: TRUE | G33: slideset.Rmd | H33: maternal-mort | I33: TRUE | J33: =IF(OR(IF(ISERROR(VLOOKUP($C33,PNGs!J:J,1,FALSE)),FALSE,TRUE),IF(ISERROR(VLOOKUP($C33,PNGs!K:K,1,FALSE)),FALSE,TRUE),IF(ISERROR(VLOOKUP($C33,PNGs!L:L,1,FALSE)),FALSE,TRUE)), TRUE,FALSE) -> TRUE | K33: Say et al, Lancet Global Health, 2014 | N33: This is pretty old…nothing newer?
A34: Good | B34: 25.8 | C34: WPP2024_GEN_F01_DEMOGRAPHIC_INDICATORS_COMPACT.xlsx | D34: data/external/ | E34: TRUE | F34: TRUE | G34: slideset.Rmd | H34: aging | I34: TRUE | J34: =IF(OR(IF(ISERROR(VLOOKUP($C34,PNGs!J:J,1,FALSE)),FALSE,TRUE),IF(ISERROR(VLOOKUP($C34,PNGs!K:K,1,FALSE)),FALSE,TRUE),IF(ISERROR(VLOOKUP($C34,PNGs!L:L,1,FALSE)),FALSE,TRUE)), TRUE,FALSE) -> TRUE | K34: UNPD WPP 2024 | N34: see "#25.0"
A35: Good | B35: 23 | C35: https://ghoapi.azureedge.net/api/sba | D35: NA | E35: NA | F35: TRUE | G35: slideset.Rmd | H35: equity | I35: TRUE | J35: =IF(OR(IF(ISERROR(VLOOKUP($C35,PNGs!J:J,1,FALSE)),FALSE,TRUE),IF(ISERROR(VLOOKUP($C35,PNGs!K:K,1,FALSE)),FALSE,TRUE),IF(ISERROR(VLOOKUP($C35,PNGs!L:L,1,FALSE)),FALSE,TRUE)), TRUE,FALSE) -> TRUE | K35: https://ghoapi.azureedge.net/api/sba | N35: Appear in slides: inequalities_sba101_decile_gho.png inequalities_sba104_edu_gho.png inequalities_sba102_resid_gho.png inequalities_sba102_subnatRegion_gho.png
A36: Good | B36: 24 | C36: https://xmart-api-public.who.int/MNCAH/MCA_FACT_DATA?$filter=INDICATOR_FK%20in%20(%22TECI_ORS%22,%22TECI_ORSZINC%22,%22TECI_PNEUHCP%22)&$select=INDICATOR_FK,YEAR_FK,COUNTRY_FK,COUNTRY_FK__CODE,ValueString,ValueNumeric,ValueLow,ValueHigh,ValueStdDev,ValueStdErr,Comments,EffectiveDate,EndDate,Status,AGEGROUP_FK,AGEGROUP_FK__CODE,Answer_FK,CauseGHE_FK,CauseGHE_FK__CODE,CauseGHEChild_FK,CauseGHEChild_FK__CODE,CauseENVCAUSE_FK,CauseENVCAUSE_FK__CODE,DatasourceLong,DatasourceShort,ImpSan_FK,ImpWater_FK,LivingArrangements_FK,MEASDEF_FK,MOTHEREDUCATION_FK,ProficiencyLevel_FK,ResideLTA_FK,RESIDENCEAREA_FK,SABDefinition_FK,SEVERITY_FK,SEVERITYHEARING_FK,SEVERITYVISION_FK,SEX_FK,WEALTHQUINTILE_FK | D36: NA | E36: NA | F36: TRUE | G36: slideset.Rmd | H36: child cov | I36: TRUE | J36: =IF(OR(IF(ISERROR(VLOOKUP($C36,PNGs!J:J,1,FALSE)),FALSE,TRUE),IF(ISERROR(VLOOKUP($C36,PNGs!K:K,1,FALSE)),FALSE,TRUE),IF(ISERROR(VLOOKUP($C36,PNGs!L:L,1,FALSE)),FALSE,TRUE)), TRUE,FALSE) -> FALSE | K36: https://xmart-api-public.who.int/MNCAH/MCA_FACT_DATA?$filter=INDICATOR_FK%20in%20(%22TECI_ORS%22,%22TECI_ORSZINC%22,%22TECI_PNEUHCP%22)&$select=INDICATOR_FK,YEAR_FK,COUNTRY_FK,COUNTRY_FK__CODE,ValueString,ValueNumeric,ValueLow,ValueHigh,ValueStdDev,ValueStdErr,Comments,EffectiveDate,EndDate,Status,AGEGROUP_FK,AGEGROUP_FK__CODE,Answer_FK,CauseGHE_FK,CauseGHE_FK__CODE,CauseGHEChild_FK,CauseGHEChild_FK__CODE,CauseENVCAUSE_FK,CauseENVCAUSE_FK__CODE,DatasourceLong,DatasourceShort,ImpSan_FK,ImpWater_FK,LivingArrangements_FK,MEASDEF_FK,MOTHEREDUCATION_FK,ProficiencyLevel_FK,ResideLTA_FK,RESIDENCEAREA_FK,SABDefinition_FK,SEVERITY_FK,SEVERITYHEARING_FK,SEVERITYVISION_FK,SEX_FK,WEALTHQUINTILE_FK | N36: Appears in slides: child_coverage_medians2010-22.png
A37: Good | B37: 25 | C37: https://xmart-api-public.who.int/MNCAH/MCA_FACT_DATA?$filter=INDICATOR_FK%20in%20(%22AGE_OVER60PCT%22)&$select=INDICATOR_FK,YEAR_FK,COUNTRY_FK,COUNTRY_FK__CODE,ValueString,ValueNumeric,ValueLow,ValueHigh,ValueStdDev,ValueStdErr,Comments,EffectiveDate,EndDate,Status,AGEGROUP_FK,AGEGROUP_FK__CODE,Answer_FK,CauseGHE_FK,CauseGHE_FK__CODE,CauseGHEChild_FK,CauseGHEChild_FK__CODE,CauseENVCAUSE_FK,CauseENVCAUSE_FK__CODE,DatasourceLong,DatasourceShort,ImpSan_FK,ImpWater_FK,LivingArrangements_FK,MEASDEF_FK,MOTHEREDUCATION_FK,ProficiencyLevel_FK,ResideLTA_FK,RESIDENCEAREA_FK,SABDefinition_FK,SEVERITY_FK,SEVERITYHEARING_FK,SEVERITYVISION_FK,SEX_FK,WEALTHQUINTILE_FK | D37: NA | E37: NA | F37: TRUE | G37: slideset.Rmd | H37: aging | I37: TRUE | J37: =IF(OR(IF(ISERROR(VLOOKUP($C37,PNGs!J:J,1,FALSE)),FALSE,TRUE),IF(ISERROR(VLOOKUP($C37,PNGs!K:K,1,FALSE)),FALSE,TRUE),IF(ISERROR(VLOOKUP($C37,PNGs!L:L,1,FALSE)),FALSE,TRUE)), TRUE,FALSE) -> FALSE | K37: https://xmart-api-public.who.int/MNCAH/MCA_FACT_DATA?$filter=INDICATOR_FK%20in%20(%22AGE_OVER60PCT%22)&$select=INDICATOR_FK,YEAR_FK,COUNTRY_FK,COUNTRY_FK__CODE,ValueString,ValueNumeric,ValueLow,ValueHigh,ValueStdDev,ValueStdErr,Comments,EffectiveDate,EndDate,Status,AGEGROUP_FK,AGEGROUP_FK__CODE,Answer_FK,CauseGHE_FK,CauseGHE_FK__CODE,CauseGHEChild_FK,CauseGHEChild_FK__CODE,CauseENVCAUSE_FK,CauseENVCAUSE_FK__CODE,DatasourceLong,DatasourceShort,ImpSan_FK,ImpWater_FK,LivingArrangements_FK,MEASDEF_FK,MOTHEREDUCATION_FK,ProficiencyLevel_FK,ResideLTA_FK,RESIDENCEAREA_FK,SABDefinition_FK,SEVERITY_FK,SEVERITYHEARING_FK,SEVERITYVISION_FK,SEX_FK,WEALTHQUINTILE_FK | N37: Don't appear in slides: age_over60pct_map-2050.png age60plspct_trends_region.png age60plspct_trends2050_region.png age60plspct_trends2050_region_labels.png age60plspct_sex_income.png age80plspct_sex_income.png aging_hale_country.png age_reside_2010-19_country.png age_reside_2010-19_country_sear-emr-afr-wpr.png age_reside_2010-19_country_amr-eur.png age_longtermcarefac_2010-22.png age_longtermcarefac_home_2010-22.png age_longtermcarefac_home_2010-21-ages65and80.png Appear in slides: age_over60pct_map.png age_over60pct_map_2030.png age60plspct_sex_region.png age80plspct_sex_region.png aging_hale_countryv2.png aging_ha_le_region_sex.png aging_ha_le_income_sex.png age_insufact70pls_sex_region.png age_labour65pls_2015-23_sex_region.png age_fall_2019_region.png age_backpain_2019_region.png age_ageism_2014_region.png
A38: Good | B38: 25.1 | C38: https://xmart-api-public.who.int/MNCAH/MCA_FACT_DATA?$filter=INDICATOR_FK%20in%20(%22AGE_OVER80PCT%22)&$select=INDICATOR_FK,YEAR_FK,COUNTRY_FK,COUNTRY_FK__CODE,ValueString,ValueNumeric,ValueLow,ValueHigh,ValueStdDev,ValueStdErr,Comments,EffectiveDate,EndDate,Status,AGEGROUP_FK,AGEGROUP_FK__CODE,Answer_FK,CauseGHE_FK,CauseGHE_FK__CODE,CauseGHEChild_FK,CauseGHEChild_FK__CODE,CauseENVCAUSE_FK,CauseENVCAUSE_FK__CODE,DatasourceLong,DatasourceShort,ImpSan_FK,ImpWater_FK,LivingArrangements_FK,MEASDEF_FK,MOTHEREDUCATION_FK,ProficiencyLevel_FK,ResideLTA_FK,RESIDENCEAREA_FK,SABDefinition_FK,SEVERITY_FK,SEVERITYHEARING_FK,SEVERITYVISION_FK,SEX_FK,WEALTHQUINTILE_FK | D38: NA | E38: NA | F38: TRUE | G38: slideset.Rmd | H38: aging | I38: TRUE | J38: =IF(OR(IF(ISERROR(VLOOKUP($C38,PNGs!J:J,1,FALSE)),FALSE,TRUE),IF(ISERROR(VLOOKUP($C38,PNGs!K:K,1,FALSE)),FALSE,TRUE),IF(ISERROR(VLOOKUP($C38,PNGs!L:L,1,FALSE)),FALSE,TRUE)), TRUE,FALSE) -> FALSE | K38: https://xmart-api-public.who.int/MNCAH/MCA_FACT_DATA?$filter=INDICATOR_FK%20in%20(%22AGE_OVER80PCT%22)&$select=INDICATOR_FK,YEAR_FK,COUNTRY_FK,COUNTRY_FK__CODE,ValueString,ValueNumeric,ValueLow,ValueHigh,ValueStdDev,ValueStdErr,Comments,EffectiveDate,EndDate,Status,AGEGROUP_FK,AGEGROUP_FK__CODE,Answer_FK,CauseGHE_FK,CauseGHE_FK__CODE,CauseGHEChild_FK,CauseGHEChild_FK__CODE,CauseENVCAUSE_FK,CauseENVCAUSE_FK__CODE,DatasourceLong,DatasourceShort,ImpSan_FK,ImpWater_FK,LivingArrangements_FK,MEASDEF_FK,MOTHEREDUCATION_FK,ProficiencyLevel_FK,ResideLTA_FK,RESIDENCEAREA_FK,SABDefinition_FK,SEVERITY_FK,SEVERITYHEARING_FK,SEVERITYVISION_FK,SEX_FK,WEALTHQUINTILE_FK | N38: see "#25.0"
A39: Good | B39: 25.2 | C39: https://xmart-api-public.who.int/MNCAH/MCA_FACT_DATA?$filter=INDICATOR_FK%20in%20(%22AGE_LE60%22,%22AGE_HALE60%22)&$select=INDICATOR_FK,YEAR_FK,COUNTRY_FK,COUNTRY_FK__CODE,ValueString,ValueNumeric,ValueLow,ValueHigh,ValueStdDev,ValueStdErr,Comments,EffectiveDate,EndDate,Status,AGEGROUP_FK,AGEGROUP_FK__CODE,Answer_FK,CauseGHE_FK,CauseGHE_FK__CODE,CauseGHEChild_FK,CauseGHEChild_FK__CODE,CauseENVCAUSE_FK,CauseENVCAUSE_FK__CODE,DatasourceLong,DatasourceShort,ImpSan_FK,ImpWater_FK,LivingArrangements_FK,MEASDEF_FK,MOTHEREDUCATION_FK,ProficiencyLevel_FK,ResideLTA_FK,RESIDENCEAREA_FK,SABDefinition_FK,SEVERITY_FK,SEVERITYHEARING_FK,SEVERITYVISION_FK,SEX_FK,WEALTHQUINTILE_FK | D39: NA | E39: NA | F39: TRUE | G39: slideset.Rmd | H39: aging | I39: TRUE | J39: =IF(OR(IF(ISERROR(VLOOKUP($C39,PNGs!J:J,1,FALSE)),FALSE,TRUE),IF(ISERROR(VLOOKUP($C39,PNGs!K:K,1,FALSE)),FALSE,TRUE),IF(ISERROR(VLOOKUP($C39,PNGs!L:L,1,FALSE)),FALSE,TRUE)), TRUE,FALSE) -> FALSE | K39: https://xmart-api-public.who.int/MNCAH/MCA_FACT_DATA?$filter=INDICATOR_FK%20in%20(%22AGE_LE60%22,%22AGE_HALE60%22)&$select=INDICATOR_FK,YEAR_FK,COUNTRY_FK,COUNTRY_FK__CODE,ValueString,ValueNumeric,ValueLow,ValueHigh,ValueStdDev,ValueStdErr,Comments,EffectiveDate,EndDate,Status,AGEGROUP_FK,AGEGROUP_FK__CODE,Answer_FK,CauseGHE_FK,CauseGHE_FK__CODE,CauseGHEChild_FK,CauseGHEChild_FK__CODE,CauseENVCAUSE_FK,CauseENVCAUSE_FK__CODE,DatasourceLong,DatasourceShort,ImpSan_FK,ImpWater_FK,LivingArrangements_FK,MEASDEF_FK,MOTHEREDUCATION_FK,ProficiencyLevel_FK,ResideLTA_FK,RESIDENCEAREA_FK,SABDefinition_FK,SEVERITY_FK,SEVERITYHEARING_FK,SEVERITYVISION_FK,SEX_FK,WEALTHQUINTILE_FK | N39: see "#25.0"
A40: Good | B40: 25.3 | C40: https://xmart-api-public.who.int/MNCAH/MCA_FACT_DATA?$filter=INDICATOR_FK%20in%20(%22AGE_MORT_TOP10%22)%20and%20YEAR_FK%20in%20(%222019%22)&$select=INDICATOR_FK,YEAR_FK,COUNTRY_FK,COUNTRY_FK__CODE,ValueString,ValueNumeric,ValueLow,ValueHigh,ValueStdDev,ValueStdErr,Comments,EffectiveDate,EndDate,Status,AGEGROUP_FK,AGEGROUP_FK__CODE,Answer_FK,CauseGHE_FK,CauseGHE_FK__CODE,CauseGHEChild_FK,CauseGHEChild_FK__CODE,CauseENVCAUSE_FK,CauseENVCAUSE_FK__CODE,DatasourceLong,DatasourceShort,ImpSan_FK,ImpWater_FK,LivingArrangements_FK,MEASDEF_FK,MOTHEREDUCATION_FK,ProficiencyLevel_FK,ResideLTA_FK,RESIDENCEAREA_FK,SABDefinition_FK,SEVERITY_FK,SEVERITYHEARING_FK,SEVERITYVISION_FK,SEX_FK,WEALTHQUINTILE_FK | D40: NA | E40: NA | F40: TRUE | G40: slideset.Rmd | H40: aging | I40: TRUE | J40: =IF(OR(IF(ISERROR(VLOOKUP($C40,PNGs!J:J,1,FALSE)),FALSE,TRUE),IF(ISERROR(VLOOKUP($C40,PNGs!K:K,1,FALSE)),FALSE,TRUE),IF(ISERROR(VLOOKUP($C40,PNGs!L:L,1,FALSE)),FALSE,TRUE)), TRUE,FALSE) -> FALSE | K40: https://xmart-api-public.who.int/MNCAH/MCA_FACT_DATA?$filter=INDICATOR_FK%20in%20(%22AGE_MORT_TOP10%22)%20and%20YEAR_FK%20in%20(%222019%22)&$select=INDICATOR_FK,YEAR_FK,COUNTRY_FK,COUNTRY_FK__CODE,ValueString,ValueNumeric,ValueLow,ValueHigh,ValueStdDev,ValueStdErr,Comments,EffectiveDate,EndDate,Status,AGEGROUP_FK,AGEGROUP_FK__CODE,Answer_FK,CauseGHE_FK,CauseGHE_FK__CODE,CauseGHEChild_FK,CauseGHEChild_FK__CODE,CauseENVCAUSE_FK,CauseENVCAUSE_FK__CODE,DatasourceLong,DatasourceShort,ImpSan_FK,ImpWater_FK,LivingArrangements_FK,MEASDEF_FK,MOTHEREDUCATION_FK,ProficiencyLevel_FK,ResideLTA_FK,RESIDENCEAREA_FK,SABDefinition_FK,SEVERITY_FK,SEVERITYHEARING_FK,SEVERITYVISION_FK,SEX_FK,WEALTHQUINTILE_FK | N40: see "#25.0"
...

Sheet PNGs
A1: code "order" | B1: PNG File name | C1: Present in Slides? | D1: Present in R code? | E1: IGME problem? | F1: GHE problem? | G1: Other data issue? | H1: R code file | I1: R code chunk | J1: Data source 1 | K1: Data source 2 | L1: Data source 3 | M1: Comment
A2: 0 | B2: NA | C2: NA | D2: NA | E2: =INDEX('Slides+PNGs'!$H:H,MATCH($B2,'Slides+PNGs'!M:M,0)) -> #N/A | F2: =INDEX('Slides+PNGs'!$I:I,MATCH($B2,'Slides+PNGs'!M:M,0)) -> #N/A | G2: =INDEX('Slides+PNGs'!$L:L,MATCH($B2,'Slides+PNGs'!M:M,0)) -> #N/A | H2: NA | I2: NA | J2: NA | K2: NA | L2: NA
A3: 1 | B3: 2023unigme_rates_nmr_imr_cmr_u5mr_dim1.png | C3: =IF(ISERROR(VLOOKUP(B3,'Slides+PNGs'!$M:$M,1,FALSE)),FALSE,TRUE) -> TRUE | D3: TRUE | E3: =INDEX('Slides+PNGs'!$H:H,MATCH($B3,'Slides+PNGs'!M:M,0)) -> Dodged | F3: =INDEX('Slides+PNGs'!$I:I,MATCH($B3,'Slides+PNGs'!M:M,0)) -> N/A | G3: =INDEX('Slides+PNGs'!$L:L,MATCH($B3,'Slides+PNGs'!M:M,0)) -> 0 | H3: slideset.Rmd | I3: newborn-mort-2021 | J3: UNIGME-2023-SDGRegion-Rates-Deaths-Under-five.xlsx
A4: 2 | B4: 2023unigme_rates_nmr_imr_cmr_u5mr_dim2.png | C4: =IF(ISERROR(VLOOKUP(B4,'Slides+PNGs'!$M:$M,1,FALSE)),FALSE,TRUE) -> TRUE | D4: TRUE | E4: =INDEX('Slides+PNGs'!$H:H,MATCH($B4,'Slides+PNGs'!M:M,0)) -> Dodged | F4: =INDEX('Slides+PNGs'!$I:I,MATCH($B4,'Slides+PNGs'!M:M,0)) -> N/A | G4: =INDEX('Slides+PNGs'!$L:L,MATCH($B4,'Slides+PNGs'!M:M,0)) -> 0 | H4: slideset.Rmd | I4: newborn-mort-2021 | J4: UNIGME-2023-SDGRegion-Rates-Deaths-Under-five.xlsx
A5: 3 | B5: 2023unigme_deaths_nmr_imr_cmr_u5mr_dim1.png | C5: =IF(ISERROR(VLOOKUP(B5,'Slides+PNGs'!$M:$M,1,FALSE)),FALSE,TRUE) -> TRUE | D5: TRUE | E5: =INDEX('Slides+PNGs'!$H:H,MATCH($B5,'Slides+PNGs'!M:M,0)) -> Dodged | F5: =INDEX('Slides+PNGs'!$I:I,MATCH($B5,'Slides+PNGs'!M:M,0)) -> N/A | G5: =INDEX('Slides+PNGs'!$L:L,MATCH($B5,'Slides+PNGs'!M:M,0)) -> 0 | H5: slideset.Rmd | I5: newborn-mort-2022 | J5: UNIGME-2023-SDGRegion-Rates-Deaths-Under-five.xlsx | M5: Was generated but not used in slides?
A6: 4 | B6: 2023unigme_deaths_nmr_imr_cmr_u5mr_dim2.png | C6: =IF(ISERROR(VLOOKUP(B6,'Slides+PNGs'!$M:$M,1,FALSE)),FALSE,TRUE) -> TRUE | D6: TRUE | E6: =INDEX('Slides+PNGs'!$H:H,MATCH($B6,'Slides+PNGs'!M:M,0)) -> Dodged | F6: =INDEX('Slides+PNGs'!$I:I,MATCH($B6,'Slides+PNGs'!M:M,0)) -> N/A | G6: =INDEX('Slides+PNGs'!$L:L,MATCH($B6,'Slides+PNGs'!M:M,0)) -> 0 | H6: slideset.Rmd | I6: newborn-mort-2023 | J6: UNIGME-2023-SDGRegion-Rates-Deaths-Under-five.xlsx
A7: 5 | B7: 2023unigme_rates_nmr_dim1.png | C7: =IF(ISERROR(VLOOKUP(B7,'Slides+PNGs'!$M:$M,1,FALSE)),FALSE,TRUE) -> TRUE | D7: TRUE | E7: =INDEX('Slides+PNGs'!$H:H,MATCH($B7,'Slides+PNGs'!M:M,0)) -> Dodged | F7: =INDEX('Slides+PNGs'!$I:I,MATCH($B7,'Slides+PNGs'!M:M,0)) -> N/A | G7: =INDEX('Slides+PNGs'!$L:L,MATCH($B7,'Slides+PNGs'!M:M,0)) -> 0 | H7: slideset.Rmd | I7: newborn-mort-2024 | J7: UNIGME-2023-SDGRegion-Rates-Deaths-Under-five.xlsx
A8: 6 | B8: 2023unigme_rates_nmr_dim2.png | C8: =IF(ISERROR(VLOOKUP(B8,'Slides+PNGs'!$M:$M,1,FALSE)),FALSE,TRUE) -> TRUE | D8: TRUE | E8: =INDEX('Slides+PNGs'!$H:H,MATCH($B8,'Slides+PNGs'!M:M,0)) -> Dodged | F8: =INDEX('Slides+PNGs'!$I:I,MATCH($B8,'Slides+PNGs'!M:M,0)) -> N/A | G8: =INDEX('Slides+PNGs'!$L:L,MATCH($B8,'Slides+PNGs'!M:M,0)) -> 0 | H8: slideset.Rmd | I8: newborn-mort-2025 | J8: UNIGME-2023-SDGRegion-Rates-Deaths-Under-five.xlsx
A9: 7 | B9: 2023unigme_deaths_nmr_dim1.png | C9: =IF(ISERROR(VLOOKUP(B9,'Slides+PNGs'!$M:$M,1,FALSE)),FALSE,TRUE) -> TRUE | D9: TRUE | E9: =INDEX('Slides+PNGs'!$H:H,MATCH($B9,'Slides+PNGs'!M:M,0)) -> Dodged | F9: =INDEX('Slides+PNGs'!$I:I,MATCH($B9,'Slides+PNGs'!M:M,0)) -> N/A | G9: =INDEX('Slides+PNGs'!$L:L,MATCH($B9,'Slides+PNGs'!M:M,0)) -> 0 | H9: slideset.Rmd | I9: newborn-mort-2025 | J9: UNIGME-2023-SDGRegion-Rates-Deaths-Under-five.xlsx
A10: 8 | B10: 2023unigme_deaths_nmr_dim2.png | C10: =IF(ISERROR(VLOOKUP(B10,'Slides+PNGs'!$M:$M,1,FALSE)),FALSE,TRUE) -> TRUE | D10: TRUE | E10: =INDEX('Slides+PNGs'!$H:H,MATCH($B10,'Slides+PNGs'!M:M,0)) -> Dodged | F10: =INDEX('Slides+PNGs'!$I:I,MATCH($B10,'Slides+PNGs'!M:M,0)) -> N/A | G10: =INDEX('Slides+PNGs'!$L:L,MATCH($B10,'Slides+PNGs'!M:M,0)) -> 0 | H10: slideset.Rmd | I10: newborn-mort-2025 | J10: UNIGME-2023-SDGRegion-Rates-Deaths-Under-five.xlsx
A11: 9 | B11: 2023unigme_rates_nmr_imr_dim1.png | C11: =IF(ISERROR(VLOOKUP(B11,'Slides+PNGs'!$M:$M,1,FALSE)),FALSE,TRUE) -> TRUE | D11: TRUE | E11: =INDEX('Slides+PNGs'!$H:H,MATCH($B11,'Slides+PNGs'!M:M,0)) -> Dodged | F11: =INDEX('Slides+PNGs'!$I:I,MATCH($B11,'Slides+PNGs'!M:M,0)) -> N/A | G11: =INDEX('Slides+PNGs'!$L:L,MATCH($B11,'Slides+PNGs'!M:M,0)) -> 0 | H11: slideset.Rmd | I11: newborn-mort-2025 | J11: UNIGME-2023-SDGRegion-Rates-Deaths-Under-five.xlsx
A12: 10 | B12: 2023unigme_rates_nmr_imr_dim2.png | C12: =IF(ISERROR(VLOOKUP(B12,'Slides+PNGs'!$M:$M,1,FALSE)),FALSE,TRUE) -> TRUE | D12: TRUE | E12: =INDEX('Slides+PNGs'!$H:H,MATCH($B12,'Slides+PNGs'!M:M,0)) -> Dodged | F12: =INDEX('Slides+PNGs'!$I:I,MATCH($B12,'Slides+PNGs'!M:M,0)) -> N/A | G12: =INDEX('Slides+PNGs'!$L:L,MATCH($B12,'Slides+PNGs'!M:M,0)) -> 0 | H12: slideset.Rmd | I12: newborn-mort-2025 | J12: UNIGME-2023-SDGRegion-Rates-Deaths-Under-five.xlsx
A13: 11 | B13: 2023unigme_deaths_nmr_imr_dim1.png | C13: =IF(ISERROR(VLOOKUP(B13,'Slides+PNGs'!$M:$M,1,FALSE)),FALSE,TRUE) -> TRUE | D13: TRUE | E13: =INDEX('Slides+PNGs'!$H:H,MATCH($B13,'Slides+PNGs'!M:M,0)) -> Dodged | F13: =INDEX('Slides+PNGs'!$I:I,MATCH($B13,'Slides+PNGs'!M:M,0)) -> N/A | G13: =INDEX('Slides+PNGs'!$L:L,MATCH($B13,'Slides+PNGs'!M:M,0)) -> 0 | H13: slideset.Rmd | I13: newborn-mort-2025 | J13: UNIGME-2023-SDGRegion-Rates-Deaths-Under-five.xlsx
A14: 12 | B14: 2023unigme_deaths_nmr_imr_dim2.png | C14: =IF(ISERROR(VLOOKUP(B14,'Slides+PNGs'!$M:$M,1,FALSE)),FALSE,TRUE) -> TRUE | D14: TRUE | E14: =INDEX('Slides+PNGs'!$H:H,MATCH($B14,'Slides+PNGs'!M:M,0)) -> Dodged | F14: =INDEX('Slides+PNGs'!$I:I,MATCH($B14,'Slides+PNGs'!M:M,0)) -> N/A | G14: =INDEX('Slides+PNGs'!$L:L,MATCH($B14,'Slides+PNGs'!M:M,0)) -> 0 | H14: slideset.Rmd | I14: newborn-mort-2025 | J14: UNIGME-2023-SDGRegion-Rates-Deaths-Under-five.xlsx
A15: 13 | B15: 2023unigme_rates_nmr_imr_cmr_dim1.png | C15: =IF(ISERROR(VLOOKUP(B15,'Slides+PNGs'!$M:$M,1,FALSE)),FALSE,TRUE) -> TRUE | D15: TRUE | E15: =INDEX('Slides+PNGs'!$H:H,MATCH($B15,'Slides+PNGs'!M:M,0)) -> Dodged | F15: =INDEX('Slides+PNGs'!$I:I,MATCH($B15,'Slides+PNGs'!M:M,0)) -> N/A | G15: =INDEX('Slides+PNGs'!$L:L,MATCH($B15,'Slides+PNGs'!M:M,0)) -> 0 | H15: slideset.Rmd | I15: newborn-mort-2025 | J15: UNIGME-2023-SDGRegion-Rates-Deaths-Under-five.xlsx
